Workbook
Name OPEN_WL_IDs: '[1]Work list'!$Q$2:INDEX('[1]Work list'!$Q:$Q,MAX(2,COUNTIF('[1]Work list'!$Q:$Q,"WL-*")+1))
Name OPEN_WL_IDs: 'Work list'!$Q$2:INDEX('Work list'!$Q:$Q,MAX(2,COUNTIF('Work list'!$Q:$Q,"WL-*")+1))
Name U2U1500: 'Work report'!$U$2
Name WL_IDs: '[1]Work list'!$B$2:INDEX('[1]Work list'!$B:$B,MAX(2,COUNTIF('[1]Work list'!$B:$B,"WL-*")+1))
Name WL_IDs: 'Work list'!$B$2:INDEX('Work list'!$B:$B,MAX(2,COUNTIF('Work list'!$B:$B,"WL-*")+1))

Sheet Setup
B1: SETUP – Quản lý điền 1 lần trước khi gửi nhân viên
AA2: A – Valuable (New/Improvement)
A3: EmployeeID | B3: 15 | AA3: B – Normal (Clarification)
A4: Employee name | B4: Đỗ Lan | AA4: C – Low value (Already documented / not followed process)
A5: Department | B5: Dev & Team Lead
A6: Company | B6: Hung IT/GM
A7: Email (Company) | B7: lanit@hung-it-solutions.com
A8: Email (Google) | B8: lanit@hung-it-solutions.com
A9: Email (private)
A10: Mobil (Company)
A11: Mobil (private)
A12: Address
A13: Pay type | B13: have to choose (Summary)
A14: Hourly rate (/h) | B14: 10
A15: Monthly salary
A16: Max hours/month | B16: 160
A17: Entry date
A18: Holidays/Year
A19: Working days
A20: Exit date
A21: Hardware/PC ID
A22: Bank Name
A23: IBAN/Account Number
A24: BIC/Swift Code
A32: Drive-link-1 | B32: https://drive.google.com/drive/folders/1gtU3qlcFI3aMBTz2z80ioSKTDObCLAxx?usp=drive_link | C32: Task-Video-11 | D32: Mitarbeiter
A33: Drive-link-2 | B33: https://drive.google.com/drive/folders/1mFbEs13a5YOUaSOAh2gZI0RXJ38N9y98?usp=drive_link | C33: SD-04 | D33: Mitarbeiter
A34: Drive-link-3 | B34: Drive-link-3
A35: Drive-link-4 | B35: Drive-link-4

Sheet Link
A1: No | B1: Go to
A2: 1 | B2: Work list
A3: =A2+1 -> 2 | B3: Work report
A4: =A3+1 -> 3 | B4: Office time approval
A5: =A4+1 -> 4 | B5: Task Library
A6: =A5+1 -> 5 | B6: Missing tasks auto
A7: =A6+1 -> 6 | B7: Missing Tasks
A8: =A7+1 -> 7 | B8: Time check for tasks
A9: =A8+1 -> 8 | B9: Summary
A10: =A9+1 -> 9 | B10: Payments
A11: =A10+1 -> 10 | B11: Vacation, holiday, illness
A12: =A11+1 -> 11 | B12: Customers
A13: =A12+1 -> 12 | B13: Messages
A14: =A13+1 -> 13 | B14: Password
... A19: =A18+1 -> 18 | B19: Work rules

Sheet Work list
A1: Date assigned | B1: WL ID | C1: Title | D1: Description | E1: Customer | F1: Priority | G1: Due date | H1: Status | I1: Progress % | J1: Last update | K1: Reason / next action | L1: Total actual time (min) | M1: Completed date | N1: Overdue | O1: WL serial (hidden) | P1: Open rank (hidden) | Q1: Open WL IDs (hidden)
B2: =IF(OR($A2<>"",$C2<>"",$D2<>"",$E2<>"",$F2<>"",$G2<>""),"WL-"&TEXT($O2,"0000"),"") | H2: =IF($B2="","",IF(N($I2)>=100,"Completed",IF(COUNTIF('Work report'!$V$2:$V$1500,$B2)=0,"Not started",IF(OR(LEFT(UPPER(TRIM($K2)),8)="BLOCKED:",LEFT(UPPER(TRIM($K2)),8)="WAITING:"),"Blocked",IF(N($I2)>0,"In progress","Not started"))))) | I2: {=IF($B2="","",IFERROR(LOOKUP(2,1/('Work report'!$V$2:$V$1500=$B2),'Work report'!$J$2:$J$1500)*100,0))} | J2: {=IF($B2="","",IFERROR(LOOKUP(2,1/('Work report'!$V$2:$V$1500=$B2),'Work report'!$A$2:$A$1500),""))} | K2: {=IF($B2="","",IFERROR(LOOKUP(2,1/('Work report'!$V$2:$V$1500=$B2),'Work report'!$P$2:$P$1500),""))} | L2: =IF($B2="","",SUMIFS('Work report'!$G$2:$G$1500,'Work report'!$V$2:$V$1500,$B2)) | M2: =IF($B2="","",IF($H2="Completed",$J2,"")) | N2: =IF(AND($C2<>"",$H2<>"Completed",$G2<>"",$G2<TODAY()),"Overdue","") | O2: 1 | P2: =IF(AND($B2<>"",$H2<>"Completed",$H2<>"Cancelled"),COUNTIFS($B$2:$B2,"<>",$H$2:$H2,"<>Completed",$H$2:$H2,"<>Cancelled"),"") | Q2: =IFERROR(INDEX($B$2:$B$1500,MATCH(ROWS($Q$2:Q2),$P$2:$P$1500,0)),"")
B3: =IF(OR($A3<>"",$C3<>"",$D3<>"",$E3<>"",$F3<>"",$G3<>""),"WL-"&TEXT($O3,"0000"),"") | H3: =IF($B3="","",IF(N($I3)>=100,"Completed",IF(COUNTIF('Work report'!$V$2:$V$1500,$B3)=0,"Not started",IF(OR(LEFT(UPPER(TRIM($K3)),8)="BLOCKED:",LEFT(UPPER(TRIM($K3)),8)="WAITING:"),"Blocked",IF(N($I3)>0,"In progress","Not started"))))) | I3: {=IF($B3="","",IFERROR(LOOKUP(2,1/('Work report'!$V$2:$V$1500=$B3),'Work report'!$J$2:$J$1500)*100,0))} | J3: {=IF($B3="","",IFERROR(LOOKUP(2,1/('Work report'!$V$2:$V$1500=$B3),'Work report'!$A$2:$A$1500),""))} | K3: {=IF($B3="","",IFERROR(LOOKUP(2,1/('Work report'!$V$2:$V$1500=$B3),'Work report'!$P$2:$P$1500),""))} | L3: =IF($B3="","",SUMIFS('Work report'!$G$2:$G$1500,'Work report'!$V$2:$V$1500,$B3)) | M3: =IF($B3="","",IF($H3="Completed",$J3,"")) | N3: =IF(AND($C3<>"",$H3<>"Completed",$G3<>"",$G3<TODAY()),"Overdue","") | O3: 2 | P3: =IF(AND($B3<>"",$H3<>"Completed",$H3<>"Cancelled"),COUNTIFS($B$2:$B3,"<>",$H$2:$H3,"<>Completed",$H$2:$H3,"<>Cancelled"),"") | Q3: =IFERROR(INDEX($B$2:$B$1500,MATCH(ROWS($Q$2:Q3),$P$2:$P$1500,0)),"")
B4: =IF(OR($A4<>"",$C4<>"",$D4<>"",$E4<>"",$F4<>"",$G4<>""),"WL-"&TEXT($O4,"0000"),"") | H4: =IF($B4="","",IF(N($I4)>=100,"Completed",IF(COUNTIF('Work report'!$V$2:$V$1500,$B4)=0,"Not started",IF(OR(LEFT(UPPER(TRIM($K4)),8)="BLOCKED:",LEFT(UPPER(TRIM($K4)),8)="WAITING:"),"Blocked",IF(N($I4)>0,"In progress","Not started"))))) | I4: {=IF($B4="","",IFERROR(LOOKUP(2,1/('Work report'!$V$2:$V$1500=$B4),'Work report'!$J$2:$J$1500)*100,0))} | J4: {=IF($B4="","",IFERROR(LOOKUP(2,1/('Work report'!$V$2:$V$1500=$B4),'Work report'!$A$2:$A$1500),""))} | K4: {=IF($B4="","",IFERROR(LOOKUP(2,1/('Work report'!$V$2:$V$1500=$B4),'Work report'!$P$2:$P$1500),""))} | L4: =IF($B4="","",SUMIFS('Work report'!$G$2:$G$1500,'Work report'!$V$2:$V$1500,$B4)) | M4: =IF($B4="","",IF($H4="Completed",$J4,"")) | N4: =IF(AND($C4<>"",$H4<>"Completed",$G4<>"",$G4<TODAY()),"Overdue","") | O4: 3 | P4: =IF(AND($B4<>"",$H4<>"Completed",$H4<>"Cancelled"),COUNTIFS($B$2:$B4,"<>",$H$2:$H4,"<>Completed",$H$2:$H4,"<>Cancelled"),"") | Q4: =IFERROR(INDEX($B$2:$B$1500,MATCH(ROWS($Q$2:Q4),$P$2:$P$1500,0)),"")
B5: =IF(OR($A5<>"",$C5<>"",$D5<>"",$E5<>"",$F5<>"",$G5<>""),"WL-"&TEXT($O5,"0000"),"") | H5: =IF($B5="","",IF(N($I5)>=100,"Completed",IF(COUNTIF('Work report'!$V$2:$V$1500,$B5)=0,"Not started",IF(OR(LEFT(UPPER(TRIM($K5)),8)="BLOCKED:",LEFT(UPPER(TRIM($K5)),8)="WAITING:"),"Blocked",IF(N($I5)>0,"In progress","Not started"))))) | I5: {=IF($B5="","",IFERROR(LOOKUP(2,1/('Work report'!$V$2:$V$1500=$B5),'Work report'!$J$2:$J$1500)*100,0))} | J5: {=IF($B5="","",IFERROR(LOOKUP(2,1/('Work report'!$V$2:$V$1500=$B5),'Work report'!$A$2:$A$1500),""))} | K5: {=IF($B5="","",IFERROR(LOOKUP(2,1/('Work report'!$V$2:$V$1500=$B5),'Work report'!$P$2:$P$1500),""))} | L5: =IF($B5="","",SUMIFS('Work report'!$G$2:$G$1500,'Work report'!$V$2:$V$1500,$B5)) | M5: =IF($B5="","",IF($H5="Completed",$J5,"")) | N5: =IF(AND($C5<>"",$H5<>"Completed",$G5<>"",$G5<TODAY()),"Overdue","") | O5: 4 | P5: =IF(AND($B5<>"",$H5<>"Completed",$H5<>"Cancelled"),COUNTIFS($B$2:$B5,"<>",$H$2:$H5,"<>Completed",$H$2:$H5,"<>Cancelled"),"") | Q5: =IFERROR(INDEX($B$2:$B$1500,MATCH(ROWS($Q$2:Q5),$P$2:$P$1500,0)),"")
B6: =IF(OR($A6<>"",$C6<>"",$D6<>"",$E6<>"",$F6<>"",$G6<>""),"WL-"&TEXT($O6,"0000"),"") | H6: =IF($B6="","",IF(N($I6)>=100,"Completed",IF(COUNTIF('Work report'!$V$2:$V$1500,$B6)=0,"Not started",IF(OR(LEFT(UPPER(TRIM($K6)),8)="BLOCKED:",LEFT(UPPER(TRIM($K6)),8)="WAITING:"),"Blocked",IF(N($I6)>0,"In progress","Not started"))))) | I6: {=IF($B6="","",IFERROR(LOOKUP(2,1/('Work report'!$V$2:$V$1500=$B6),'Work report'!$J$2:$J$1500)*100,0))} | J6: {=IF($B6="","",IFERROR(LOOKUP(2,1/('Work report'!$V$2:$V$1500=$B6),'Work report'!$A$2:$A$1500),""))} | K6: {=IF($B6="","",IFERROR(LOOKUP(2,1/('Work report'!$V$2:$V$1500=$B6),'Work report'!$P$2:$P$1500),""))} | L6: =IF($B6="","",SUMIFS('Work report'!$G$2:$G$1500,'Work report'!$V$2:$V$1500,$B6)) | M6: =IF($B6="","",IF($H6="Completed",$J6,"")) | N6: =IF(AND($C6<>"",$H6<>"Completed",$G6<>"",$G6<TODAY()),"Overdue","") | O6: 5 | P6: =IF(AND($B6<>"",$H6<>"Completed",$H6<>"Cancelled"),COUNTIFS($B$2:$B6,"<>",$H$2:$H6,"<>Completed",$H$2:$H6,"<>Cancelled"),"") | Q6: =IFERROR(INDEX($B$2:$B$1500,MATCH(ROWS($Q$2:Q6),$P$2:$P$1500,0)),"")
B7: =IF(OR($A7<>"",$C7<>"",$D7<>"",$E7<>"",$F7<>"",$G7<>""),"WL-"&TEXT($O7,"0000"),"") | H7: =IF($B7="","",IF(N($I7)>=100,"Completed",IF(COUNTIF('Work report'!$V$2:$V$1500,$B7)=0,"Not started",IF(OR(LEFT(UPPER(TRIM($K7)),8)="BLOCKED:",LEFT(UPPER(TRIM($K7)),8)="WAITING:"),"Blocked",IF(N($I7)>0,"In progress","Not started"))))) | I7: {=IF($B7="","",IFERROR(LOOKUP(2,1/('Work report'!$V$2:$V$1500=$B7),'Work report'!$J$2:$J$1500)*100,0))} | J7: {=IF($B7="","",IFERROR(LOOKUP(2,1/('Work report'!$V$2:$V$1500=$B7),'Work report'!$A$2:$A$1500),""))} | K7: {=IF($B7="","",IFERROR(LOOKUP(2,1/('Work report'!$V$2:$V$1500=$B7),'Work report'!$P$2:$P$1500),""))} | L7: =IF($B7="","",SUMIFS('Work report'!$G$2:$G$1500,'Work report'!$V$2:$V$1500,$B7)) | M7: =IF($B7="","",IF($H7="Completed",$J7,"")) | N7: =IF(AND($C7<>"",$H7<>"Completed",$G7<>"",$G7<TODAY()),"Overdue","") | O7: 6 | P7: =IF(AND($B7<>"",$H7<>"Completed",$H7<>"Cancelled"),COUNTIFS($B$2:$B7,"<>",$H$2:$H7,"<>Completed",$H$2:$H7,"<>Cancelled"),"") | Q7: =IFERROR(INDEX($B$2:$B$1500,MATCH(ROWS($Q$2:Q7),$P$2:$P$1500,0)),"")
B8: =IF(OR($A8<>"",$C8<>"",$D8<>"",$E8<>"",$F8<>"",$G8<>""),"WL-"&TEXT($O8,"0000"),"") | H8: =IF($B8="","",IF(N($I8)>=100,"Completed",IF(COUNTIF('Work report'!$V$2:$V$1500,$B8)=0,"Not started",IF(OR(LEFT(UPPER(TRIM($K8)),8)="BLOCKED:",LEFT(UPPER(TRIM($K8)),8)="WAITING:"),"Blocked",IF(N($I8)>0,"In progress","Not started"))))) | I8: {=IF($B8="","",IFERROR(LOOKUP(2,1/('Work report'!$V$2:$V$1500=$B8),'Work report'!$J$2:$J$1500)*100,0))} | J8: {=IF($B8="","",IFERROR(LOOKUP(2,1/('Work report'!$V$2:$V$1500=$B8),'Work report'!$A$2:$A$1500),""))} | K8: {=IF($B8="","",IFERROR(LOOKUP(2,1/('Work report'!$V$2:$V$1500=$B8),'Work report'!$P$2:$P$1500),""))} | L8: =IF($B8="","",SUMIFS('Work report'!$G$2:$G$1500,'Work report'!$V$2:$V$1500,$B8)) | M8: =IF($B8="","",IF($H8="Completed",$J8,"")) | N8: =IF(AND($C8<>"",$H8<>"Completed",$G8<>"",$G8<TODAY()),"Overdue","") | O8: 7 | P8: =IF(AND($B8<>"",$H8<>"Completed",$H8<>"Cancelled"),COUNTIFS($B$2:$B8,"<>",$H$2:$H8,"<>Completed",$H$2:$H8,"<>Cancelled"),"") | Q8: =IFERROR(INDEX($B$2:$B$1500,MATCH(ROWS($Q$2:Q8),$P$2:$P$1500,0)),"")
B9: =IF(OR($A9<>"",$C9<>"",$D9<>"",$E9<>"",$F9<>"",$G9<>""),"WL-"&TEXT($O9,"0000"),"") | H9: =IF($B9="","",IF(N($I9)>=100,"Completed",IF(COUNTIF('Work report'!$V$2:$V$1500,$B9)=0,"Not started",IF(OR(LEFT(UPPER(TRIM($K9)),8)="BLOCKED:",LEFT(UPPER(TRIM($K9)),8)="WAITING:"),"Blocked",IF(N($I9)>0,"In progress","Not started"))))) | I9: {=IF($B9="","",IFERROR(LOOKUP(2,1/('Work report'!$V$2:$V$1500=$B9),'Work report'!$J$2:$J$1500)*100,0))} | J9: {=IF($B9="","",IFERROR(LOOKUP(2,1/('Work report'!$V$2:$V$1500=$B9),'Work report'!$A$2:$A$1500),""))} | K9: {=IF($B9="","",IFERROR(LOOKUP(2,1/('Work report'!$V$2:$V$1500=$B9),'Work report'!$P$2:$P$1500),""))} | L9: =IF($B9="","",SUMIFS('Work report'!$G$2:$G$1500,'Work report'!$V$2:$V$1500,$B9)) | M9: =IF($B9="","",IF($H9="Completed",$J9,"")) | N9: =IF(AND($C9<>"",$H9<>"Completed",$G9<>"",$G9<TODAY()),"Overdue","") | O9: 8 | P9: =IF(AND($B9<>"",$H9<>"Completed",$H9<>"Cancelled"),COUNTIFS($B$2:$B9,"<>",$H$2:$H9,"<>Completed",$H$2:$H9,"<>Cancelled"),"") | Q9: =IFERROR(INDEX($B$2:$B$1500,MATCH(ROWS($Q$2:Q9),$P$2:$P$1500,0)),"")
B10: =IF(OR($A10<>"",$C10<>"",$D10<>"",$E10<>"",$F10<>"",$G10<>""),"WL-"&TEXT($O10,"0000"),"") | H10: =IF($B10="","",IF(N($I10)>=100,"Completed",IF(COUNTIF('Work report'!$V$2:$V$1500,$B10)=0,"Not started",IF(OR(LEFT(UPPER(TRIM($K10)),8)="BLOCKED:",LEFT(UPPER(TRIM($K10)),8)="WAITING:"),"Blocked",IF(N($I10)>0,"In progress","Not started"))))) | I10: {=IF($B10="","",IFERROR(LOOKUP(2,1/('Work report'!$V$2:$V$1500=$B10),'Work report'!$J$2:$J$1500)*100,0))} | J10: {=IF($B10="","",IFERROR(LOOKUP(2,1/('Work report'!$V$2:$V$1500=$B10),'Work report'!$A$2:$A$1500),""))} | K10: {=IF($B10="","",IFERROR(LOOKUP(2,1/('Work report'!$V$2:$V$1500=$B10),'Work report'!$P$2:$P$1500),""))} | L10: =IF($B10="","",SUMIFS('Work report'!$G$2:$G$1500,'Work report'!$V$2:$V$1500,$B10)) | M10: =IF($B10="","",IF($H10="Completed",$J10,"")) | N10: =IF(AND($C10<>"",$H10<>"Completed",$G10<>"",$G10<TODAY()),"Overdue","") | O10: 9 | P10: =IF(AND($B10<>"",$H10<>"Completed",$H10<>"Cancelled"),COUNTIFS($B$2:$B10,"<>",$H$2:$H10,"<>Completed",$H$2:$H10,"<>Cancelled"),"") | Q10: =IFERROR(INDEX($B$2:$B$1500,MATCH(ROWS($Q$2:Q10),$P$2:$P$1500,0)),"")
B11: =IF(OR($A11<>"",$C11<>"",$D11<>"",$E11<>"",$F11<>"",$G11<>""),"WL-"&TEXT($O11,"0000"),"") | H11: =IF($B11="","",IF(N($I11)>=100,"Completed",IF(COUNTIF('Work report'!$V$2:$V$1500,$B11)=0,"Not started",IF(OR(LEFT(UPPER(TRIM($K11)),8)="BLOCKED:",LEFT(UPPER(TRIM($K11)),8)="WAITING:"),"Blocked",IF(N($I11)>0,"In progress","Not started"))))) | I11: {=IF($B11="","",IFERROR(LOOKUP(2,1/('Work report'!$V$2:$V$1500=$B11),'Work report'!$J$2:$J$1500)*100,0))} | J11: {=IF($B11="","",IFERROR(LOOKUP(2,1/('Work report'!$V$2:$V$1500=$B11),'Work report'!$A$2:$A$1500),""))} | K11: {=IF($B11="","",IFERROR(LOOKUP(2,1/('Work report'!$V$2:$V$1500=$B11),'Work report'!$P$2:$P$1500),""))} | L11: =IF($B11="","",SUMIFS('Work report'!$G$2:$G$1500,'Work report'!$V$2:$V$1500,$B11)) | M11: =IF($B11="","",IF($H11="Completed",$J11,"")) | N11: =IF(AND($C11<>"",$H11<>"Completed",$G11<>"",$G11<TODAY()),"Overdue","") | O11: 10 | P11: =IF(AND($B11<>"",$H11<>"Completed",$H11<>"Cancelled"),COUNTIFS($B$2:$B11,"<>",$H$2:$H11,"<>Completed",$H$2:$H11,"<>Cancelled"),"") | Q11: =IFERROR(INDEX($B$2:$B$1500,MATCH(ROWS($Q$2:Q11),$P$2:$P$1500,0)),"")
B12: =IF(OR($A12<>"",$C12<>"",$D12<>"",$E12<>"",$F12<>"",$G12<>""),"WL-"&TEXT($O12,"0000"),"") | H12: =IF($B12="","",IF(N($I12)>=100,"Completed",IF(COUNTIF('Work report'!$V$2:$V$1500,$B12)=0,"Not started",IF(OR(LEFT(UPPER(TRIM($K12)),8)="BLOCKED:",LEFT(UPPER(TRIM($K12)),8)="WAITING:"),"Blocked",IF(N($I12)>0,"In progress","Not started"))))) | I12: {=IF($B12="","",IFERROR(LOOKUP(2,1/('Work report'!$V$2:$V$1500=$B12),'Work report'!$J$2:$J$1500)*100,0))} | J12: {=IF($B12="","",IFERROR(LOOKUP(2,1/('Work report'!$V$2:$V$1500=$B12),'Work report'!$A$2:$A$1500),""))} | K12: {=IF($B12="","",IFERROR(LOOKUP(2,1/('Work report'!$V$2:$V$1500=$B12),'Work report'!$P$2:$P$1500),""))} | L12: =IF($B12="","",SUMIFS('Work report'!$G$2:$G$1500,'Work report'!$V$2:$V$1500,$B12)) | M12: =IF($B12="","",IF($H12="Completed",$J12,"")) | N12: =IF(AND($C12<>"",$H12<>"Completed",$G12<>"",$G12<TODAY()),"Overdue","") | O12: 11 | P12: =IF(AND($B12<>"",$H12<>"Completed",$H12<>"Cancelled"),COUNTIFS($B$2:$B12,"<>",$H$2:$H12,"<>Completed",$H$2:$H12,"<>Cancelled"),"") | Q12: =IFERROR(INDEX($B$2:$B$1500,MATCH(ROWS($Q$2:Q12),$P$2:$P$1500,0)),"")
B13: =IF(OR($A13<>"",$C13<>"",$D13<>"",$E13<>"",$F13<>"",$G13<>""),"WL-"&TEXT($O13,"0000"),"") | H13: =IF($B13="","",IF(N($I13)>=100,"Completed",IF(COUNTIF('Work report'!$V$2:$V$1500,$B13)=0,"Not started",IF(OR(LEFT(UPPER(TRIM($K13)),8)="BLOCKED:",LEFT(UPPER(TRIM($K13)),8)="WAITING:"),"Blocked",IF(N($I13)>0,"In progress","Not started"))))) | I13: {=IF($B13="","",IFERROR(LOOKUP(2,1/('Work report'!$V$2:$V$1500=$B13),'Work report'!$J$2:$J$1500)*100,0))} | J13: {=IF($B13="","",IFERROR(LOOKUP(2,1/('Work report'!$V$2:$V$1500=$B13),'Work report'!$A$2:$A$1500),""))} | K13: {=IF($B13="","",IFERROR(LOOKUP(2,1/('Work report'!$V$2:$V$1500=$B13),'Work report'!$P$2:$P$1500),""))} | L13: =IF($B13="","",SUMIFS('Work report'!$G$2:$G$1500,'Work report'!$V$2:$V$1500,$B13)) | M13: =IF($B13="","",IF($H13="Completed",$J13,"")) | N13: =IF(AND($C13<>"",$H13<>"Completed",$G13<>"",$G13<TODAY()),"Overdue","") | O13: 12 | P13: =IF(AND($B13<>"",$H13<>"Completed",$H13<>"Cancelled"),COUNTIFS($B$2:$B13,"<>",$H$2:$H13,"<>Completed",$H$2:$H13,"<>Cancelled"),"") | Q13: =IFERROR(INDEX($B$2:$B$1500,MATCH(ROWS($Q$2:Q13),$P$2:$P$1500,0)),"")
... B1500: =IF(OR($A1500<>"",$C1500<>"",$D1500<>"",$E1500<>"",$F1500<>"",$G1500<>""),"WL-"&TEXT($O1500,"0000"),"") | H1500: =IF($B1500="","",IF(N($I1500)>=100,"Completed",IF(COUNTIF('Work report'!$V$2:$V$1500,$B1500)=0,"Not started",IF(OR(LEFT(UPPER(TRIM($K1500)),8)="BLOCKED:",LEFT(UPPER(TRIM($K1500)),8)="WAITING:"),"Blocked",IF(N($I1500)>0,"In progress","Not started"))))) | I1500: {=IF($B1500="","",IFERROR(LOOKUP(2,1/('Work report'!$V$2:$V$1500=$B1500),'Work report'!$J$2:$J$1500)*100,0))} | J1500: {=IF($B1500="","",IFERROR(LOOKUP(2,1/('Work report'!$V$2:$V$1500=$B1500),'Work report'!$A$2:$A$1500),""))} | K1500: {=IF($B1500="","",IFERROR(LOOKUP(2,1/('Work report'!$V$2:$V$1500=$B1500),'Work report'!$P$2:$P$1500),""))} | L1500: =IF($B1500="","",SUMIFS('Work report'!$G$2:$G$1500,'Work report'!$V$2:$V$1500,$B1500)) | M1500: =IF($B1500="","",IF($H1500="Completed",$J1500,"")) | N1500: =IF(AND($C1500<>"",$H1500<>"Completed",$G1500<>"",$G1500<TODAY()),"Overdue","") | O1500: 1499 | P1500: =IF(AND($B1500<>"",$H1500<>"Completed",$H1500<>"Cancelled"),COUNTIFS($B$2:$B1500,"<>",$H$2:$H1500,"<>Completed",$H$2:$H1500,"<>Cancelled"),"") | Q1500: =IFERROR(INDEX($B$2:$B$1500,MATCH(ROWS($Q$2:Q1500),$P$2:$P$1500,0)),"")

Sheet Work report
A1: Date | B1: Task ID | C1: Quantity | D1: Task name | E1: Description | F1: Std time (min) | G1: Actual time (min) | H1: Delta (min) | I1: Credited time (min) | J1: Completion % | K1: Std time issue? | L1: Number of videos recorded | M1: Video duration (min) | N1: Time difference | O1: Video type | P1: Note | Q1: Link | R1: Task name 2001, 2002 | S1: Description 2001, 2002 | T1: Customer | U1: Rating | V1: WL ID (type/paste; dropdown = open tasks) | W1: Drive check (Drive-link-1 / N3) | X1: Helper key | Y1: Helper total count | Z1: Helper running count | AA1: Helper output index | AB1: Link2 | AC1: Link3 | AD1: Link4
C2: =IF($B2="","",1) | D2: =IF($B2="","",IFERROR(VLOOKUP($B2,'Task library'!$A:$E,2,FALSE()),"")) | E2: =IF($B2="","",IFERROR(VLOOKUP($B2,'Task library'!$A:$E,3,FALSE()),"")) | F2: =IF($B2="","",IFERROR(VLOOKUP($B2,'Task library'!$A:$E,4,FALSE()),"")) | H2: =IF(OR($B2="",$I2=""),"",IFERROR($I2-$G2,"")) | I2: =IF($B2="","",IF($G2="","",IF(ISNUMBER($U2),MAX(0,MIN($G2,$G2/10*$U2)),IF(OR(NOT(ISNUMBER($M2)),$M2<=0,$Q2="",NOT(OR($W2="OK",$W2="FILE LINK (check)"))),"",IF($G2<=$M2+5,$G2,$M2))))) | L2: =IF($B2="","",1) | N2: =IF($B2="","",IF($G2="","",IF(ISNUMBER($M2),$M2,0)-$G2)) | W2: =IF($B2="","",IF($Q2="","MISSING LINK",IF(NOT(ISNUMBER(SEARCH("drive.google.com",$Q2))),"NOT DRIVE LINK",IFERROR(IF(ISNUMBER(SEARCH(MID(Summary!$N$3,SEARCH("/folders/",Summary!$N$3)+9,SEARCH("?",Summary!$N$3&"?")-(SEARCH("/folders/",Summary!$N$3)+9)),$Q2)),"OK",IF(ISNUMBER(SEARCH("/file/d/",$Q2)),"FILE LINK (check)","WRONG DRIVE")),"WRONG DRIVE")))) | X2: =IF(OR($B2=2001,$B2=2002),IF(OR(LEN(TRIM($R2))=0,LEN(TRIM($S2))=0),"",TRIM($R2)&" | "&TRIM($S2)),"") | Y2: =IF($X2="","",COUNTIF($X$2:$X$1500,$X2)) | Z2: =IF($X2="","",COUNTIF($X$2:$X2,$X2)) | AA2: =IF(AND($X2<>"",$Y2>=3,$Z2=1),COUNTIF($AA$1:AA1,">0")+1,"")
C3: =IF($B3="","",1) | D3: =IF($B3="","",IFERROR(VLOOKUP($B3,'Task library'!$A:$E,2,FALSE()),"")) | E3: =IF($B3="","",IFERROR(VLOOKUP($B3,'Task library'!$A:$E,3,FALSE()),"")) | F3: =IF($B3="","",IFERROR(VLOOKUP($B3,'Task library'!$A:$E,4,FALSE()),"")) | H3: =IF(OR($B3="",$I3=""),"",IFERROR($I3-$G3,"")) | I3: =IF($B3="","",IF($G3="","",IF(ISNUMBER($U3),MAX(0,MIN($G3,$G3/10*$U3)),IF(OR(NOT(ISNUMBER($M3)),$M3<=0,$Q3="",NOT(OR($W3="OK",$W3="FILE LINK (check)"))),"",IF($G3<=$M3+5,$G3,$M3))))) | L3: =IF($B3="","",1) | N3: =IF($B3="","",IF($G3="","",IF(ISNUMBER($M3),$M3,0)-$G3)) | W3: =IF($B3="","",IF($Q3="","MISSING LINK",IF(NOT(ISNUMBER(SEARCH("drive.google.com",$Q3))),"NOT DRIVE LINK",IFERROR(IF(ISNUMBER(SEARCH(MID(Summary!$N$3,SEARCH("/folders/",Summary!$N$3)+9,SEARCH("?",Summary!$N$3&"?")-(SEARCH("/folders/",Summary!$N$3)+9)),$Q3)),"OK",IF(ISNUMBER(SEARCH("/file/d/",$Q3)),"FILE LINK (check)","WRONG DRIVE")),"WRONG DRIVE")))) | X3: =IF(OR($B3=2001,$B3=2002),IF(OR(LEN(TRIM($R3))=0,LEN(TRIM($S3))=0),"",TRIM($R3)&" | "&TRIM($S3)),"") | Y3: =IF($X3="","",COUNTIF($X$2:$X$1500,$X3)) | Z3: =IF($X3="","",COUNTIF($X$2:$X3,$X3)) | AA3: =IF(AND($X3<>"",$Y3>=3,$Z3=1),COUNTIF($AA$1:AA2,">0")+1,"")
C4: =IF($B4="","",1) | D4: =IF($B4="","",IFERROR(VLOOKUP($B4,'Task library'!$A:$E,2,FALSE()),"")) | E4: =IF($B4="","",IFERROR(VLOOKUP($B4,'Task library'!$A:$E,3,FALSE()),"")) | F4: =IF($B4="","",IFERROR(VLOOKUP($B4,'Task library'!$A:$E,4,FALSE()),"")) | H4: =IF(OR($B4="",$I4=""),"",IFERROR($I4-$G4,"")) | I4: =IF($B4="","",IF($G4="","",IF(ISNUMBER($U4),MAX(0,MIN($G4,$G4/10*$U4)),IF(OR(NOT(ISNUMBER($M4)),$M4<=0,$Q4="",NOT(OR($W4="OK",$W4="FILE LINK (check)"))),"",IF($G4<=$M4+5,$G4,$M4))))) | L4: =IF($B4="","",1) | N4: =IF($B4="","",IF($G4="","",IF(ISNUMBER($M4),$M4,0)-$G4)) | W4: =IF($B4="","",IF($Q4="","MISSING LINK",IF(NOT(ISNUMBER(SEARCH("drive.google.com",$Q4))),"NOT DRIVE LINK",IFERROR(IF(ISNUMBER(SEARCH(MID(Summary!$N$3,SEARCH("/folders/",Summary!$N$3)+9,SEARCH("?",Summary!$N$3&"?")-(SEARCH("/folders/",Summary!$N$3)+9)),$Q4)),"OK",IF(ISNUMBER(SEARCH("/file/d/",$Q4)),"FILE LINK (check)","WRONG DRIVE")),"WRONG DRIVE")))) | X4: =IF(OR($B4=2001,$B4=2002),IF(OR(LEN(TRIM($R4))=0,LEN(TRIM($S4))=0),"",TRIM($R4)&" | "&TRIM($S4)),"") | Y4: =IF($X4="","",COUNTIF($X$2:$X$1500,$X4)) | Z4: =IF($X4="","",COUNTIF($X$2:$X4,$X4)) | AA4: =IF(AND($X4<>"",$Y4>=3,$Z4=1),COUNTIF($AA$1:AA3,">0")+1,"")
C5: =IF($B5="","",1) | D5: =IF($B5="","",IFERROR(VLOOKUP($B5,'Task library'!$A:$E,2,FALSE()),"")) | E5: =IF($B5="","",IFERROR(VLOOKUP($B5,'Task library'!$A:$E,3,FALSE()),"")) | F5: =IF($B5="","",IFERROR(VLOOKUP($B5,'Task library'!$A:$E,4,FALSE()),"")) | H5: =IF(OR($B5="",$I5=""),"",IFERROR($I5-$G5,"")) | I5: =IF($B5="","",IF($G5="","",IF(ISNUMBER($U5),MAX(0,MIN($G5,$G5/10*$U5)),IF(OR(NOT(ISNUMBER($M5)),$M5<=0,$Q5="",NOT(OR($W5="OK",$W5="FILE LINK (check)"))),"",IF($G5<=$M5+5,$G5,$M5))))) | L5: =IF($B5="","",1) | N5: =IF($B5="","",IF($G5="","",IF(ISNUMBER($M5),$M5,0)-$G5)) | W5: =IF($B5="","",IF($Q5="","MISSING LINK",IF(NOT(ISNUMBER(SEARCH("drive.google.com",$Q5))),"NOT DRIVE LINK",IFERROR(IF(ISNUMBER(SEARCH(MID(Summary!$N$3,SEARCH("/folders/",Summary!$N$3)+9,SEARCH("?",Summary!$N$3&"?")-(SEARCH("/folders/",Summary!$N$3)+9)),$Q5)),"OK",IF(ISNUMBER(SEARCH("/file/d/",$Q5)),"FILE LINK (check)","WRONG DRIVE")),"WRONG DRIVE")))) | X5: =IF(OR($B5=2001,$B5=2002),IF(OR(LEN(TRIM($R5))=0,LEN(TRIM($S5))=0),"",TRIM($R5)&" | "&TRIM($S5)),"") | Y5: =IF($X5="","",COUNTIF($X$2:$X$1500,$X5)) | Z5: =IF($X5="","",COUNTIF($X$2:$X5,$X5)) | AA5: =IF(AND($X5<>"",$Y5>=3,$Z5=1),COUNTIF($AA$1:AA4,">0")+1,"")
C6: =IF($B6="","",1) | D6: =IF($B6="","",IFERROR(VLOOKUP($B6,'Task library'!$A:$E,2,FALSE()),"")) | E6: =IF($B6="","",IFERROR(VLOOKUP($B6,'Task library'!$A:$E,3,FALSE()),"")) | F6: =IF($B6="","",IFERROR(VLOOKUP($B6,'Task library'!$A:$E,4,FALSE()),"")) | H6: =IF(OR($B6="",$I6=""),"",IFERROR($I6-$G6,"")) | I6: =IF($B6="","",IF($G6="","",IF(ISNUMBER($U6),MAX(0,MIN($G6,$G6/10*$U6)),IF(OR(NOT(ISNUMBER($M6)),$M6<=0,$Q6="",NOT(OR($W6="OK",$W6="FILE LINK (check)"))),"",IF($G6<=$M6+5,$G6,$M6))))) | L6: =IF($B6="","",1) | N6: =IF($B6="","",IF($G6="","",IF(ISNUMBER($M6),$M6,0)-$G6)) | W6: =IF($B6="","",IF($Q6="","MISSING LINK",IF(NOT(ISNUMBER(SEARCH("drive.google.com",$Q6))),"NOT DRIVE LINK",IFERROR(IF(ISNUMBER(SEARCH(MID(Summary!$N$3,SEARCH("/folders/",Summary!$N$3)+9,SEARCH("?",Summary!$N$3&"?")-(SEARCH("/folders/",Summary!$N$3)+9)),$Q6)),"OK",IF(ISNUMBER(SEARCH("/file/d/",$Q6)),"FILE LINK (check)","WRONG DRIVE")),"WRONG DRIVE")))) | X6: =IF(OR($B6=2001,$B6=2002),IF(OR(LEN(TRIM($R6))=0,LEN(TRIM($S6))=0),"",TRIM($R6)&" | "&TRIM($S6)),"") | Y6: =IF($X6="","",COUNTIF($X$2:$X$1500,$X6)) | Z6: =IF($X6="","",COUNTIF($X$2:$X6,$X6)) | AA6: =IF(AND($X6<>"",$Y6>=3,$Z6=1),COUNTIF($AA$1:AA5,">0")+1,"")
C7: =IF($B7="","",1) | D7: =IF($B7="","",IFERROR(VLOOKUP($B7,'Task library'!$A:$E,2,FALSE()),"")) | E7: =IF($B7="","",IFERROR(VLOOKUP($B7,'Task library'!$A:$E,3,FALSE()),"")) | F7: =IF($B7="","",IFERROR(VLOOKUP($B7,'Task library'!$A:$E,4,FALSE()),"")) | H7: =IF(OR($B7="",$I7=""),"",IFERROR($I7-$G7,"")) | I7: =IF($B7="","",IF($G7="","",IF(ISNUMBER($U7),MAX(0,MIN($G7,$G7/10*$U7)),IF(OR(NOT(ISNUMBER($M7)),$M7<=0,$Q7="",NOT(OR($W7="OK",$W7="FILE LINK (check)"))),"",IF($G7<=$M7+5,$G7,$M7))))) | L7: =IF($B7="","",1) | N7: =IF($B7="","",IF($G7="","",IF(ISNUMBER($M7),$M7,0)-$G7)) | W7: =IF($B7="","",IF($Q7="","MISSING LINK",IF(NOT(ISNUMBER(SEARCH("drive.google.com",$Q7))),"NOT DRIVE LINK",IFERROR(IF(ISNUMBER(SEARCH(MID(Summary!$N$3,SEARCH("/folders/",Summary!$N$3)+9,SEARCH("?",Summary!$N$3&"?")-(SEARCH("/folders/",Summary!$N$3)+9)),$Q7)),"OK",IF(ISNUMBER(SEARCH("/file/d/",$Q7)),"FILE LINK (check)","WRONG DRIVE")),"WRONG DRIVE")))) | X7: =IF(OR($B7=2001,$B7=2002),IF(OR(LEN(TRIM($R7))=0,LEN(TRIM($S7))=0),"",TRIM($R7)&" | "&TRIM($S7)),"") | Y7: =IF($X7="","",COUNTIF($X$2:$X$1500,$X7)) | Z7: =IF($X7="","",COUNTIF($X$2:$X7,$X7)) | AA7: =IF(AND($X7<>"",$Y7>=3,$Z7=1),COUNTIF($AA$1:AA6,">0")+1,"")
C8: =IF($B8="","",1) | D8: =IF($B8="","",IFERROR(VLOOKUP($B8,'Task library'!$A:$E,2,FALSE()),"")) | E8: =IF($B8="","",IFERROR(VLOOKUP($B8,'Task library'!$A:$E,3,FALSE()),"")) | F8: =IF($B8="","",IFERROR(VLOOKUP($B8,'Task library'!$A:$E,4,FALSE()),"")) | H8: =IF(OR($B8="",$I8=""),"",IFERROR($I8-$G8,"")) | I8: =IF($B8="","",IF($G8="","",IF(ISNUMBER($U8),MAX(0,MIN($G8,$G8/10*$U8)),IF(OR(NOT(ISNUMBER($M8)),$M8<=0,$Q8="",NOT(OR($W8="OK",$W8="FILE LINK (check)"))),"",IF($G8<=$M8+5,$G8,$M8))))) | L8: =IF($B8="","",1) | N8: =IF($B8="","",IF($G8="","",IF(ISNUMBER($M8),$M8,0)-$G8)) | W8: =IF($B8="","",IF($Q8="","MISSING LINK",IF(NOT(ISNUMBER(SEARCH("drive.google.com",$Q8))),"NOT DRIVE LINK",IFERROR(IF(ISNUMBER(SEARCH(MID(Summary!$N$3,SEARCH("/folders/",Summary!$N$3)+9,SEARCH("?",Summary!$N$3&"?")-(SEARCH("/folders/",Summary!$N$3)+9)),$Q8)),"OK",IF(ISNUMBER(SEARCH("/file/d/",$Q8)),"FILE LINK (check)","WRONG DRIVE")),"WRONG DRIVE")))) | X8: =IF(OR($B8=2001,$B8=2002),IF(OR(LEN(TRIM($R8))=0,LEN(TRIM($S8))=0),"",TRIM($R8)&" | "&TRIM($S8)),"") | Y8: =IF($X8="","",COUNTIF($X$2:$X$1500,$X8)) | Z8: =IF($X8="","",COUNTIF($X$2:$X8,$X8)) | AA8: =IF(AND($X8<>"",$Y8>=3,$Z8=1),COUNTIF($AA$1:AA7,">0")+1,"")
C9: =IF($B9="","",1) | D9: =IF($B9="","",IFERROR(VLOOKUP($B9,'Task library'!$A:$E,2,FALSE()),"")) | E9: =IF($B9="","",IFERROR(VLOOKUP($B9,'Task library'!$A:$E,3,FALSE()),"")) | F9: =IF($B9="","",IFERROR(VLOOKUP($B9,'Task library'!$A:$E,4,FALSE()),"")) | H9: =IF(OR($B9="",$I9=""),"",IFERROR($I9-$G9,"")) | I9: =IF($B9="","",IF($G9="","",IF(ISNUMBER($U9),MAX(0,MIN($G9,$G9/10*$U9)),IF(OR(NOT(ISNUMBER($M9)),$M9<=0,$Q9="",NOT(OR($W9="OK",$W9="FILE LINK (check)"))),"",IF($G9<=$M9+5,$G9,$M9))))) | L9: =IF($B9="","",1) | N9: =IF($B9="","",IF($G9="","",IF(ISNUMBER($M9),$M9,0)-$G9)) | W9: =IF($B9="","",IF($Q9="","MISSING LINK",IF(NOT(ISNUMBER(SEARCH("drive.google.com",$Q9))),"NOT DRIVE LINK",IFERROR(IF(ISNUMBER(SEARCH(MID(Summary!$N$3,SEARCH("/folders/",Summary!$N$3)+9,SEARCH("?",Summary!$N$3&"?")-(SEARCH("/folders/",Summary!$N$3)+9)),$Q9)),"OK",IF(ISNUMBER(SEARCH("/file/d/",$Q9)),"FILE LINK (check)","WRONG DRIVE")),"WRONG DRIVE")))) | X9: =IF(OR($B9=2001,$B9=2002),IF(OR(LEN(TRIM($R9))=0,LEN(TRIM($S9))=0),"",TRIM($R9)&" | "&TRIM($S9)),"") | Y9: =IF($X9="","",COUNTIF($X$2:$X$1500,$X9)) | Z9: =IF($X9="","",COUNTIF($X$2:$X9,$X9)) | AA9: =IF(AND($X9<>"",$Y9>=3,$Z9=1),COUNTIF($AA$1:AA8,">0")+1,"")
C10: =IF($B10="","",1) | D10: =IF($B10="","",IFERROR(VLOOKUP($B10,'Task library'!$A:$E,2,FALSE()),"")) | E10: =IF($B10="","",IFERROR(VLOOKUP($B10,'Task library'!$A:$E,3,FALSE()),"")) | F10: =IF($B10="","",IFERROR(VLOOKUP($B10,'Task library'!$A:$E,4,FALSE()),"")) | H10: =IF(OR($B10="",$I10=""),"",IFERROR($I10-$G10,"")) | I10: =IF($B10="","",IF($G10="","",IF(ISNUMBER($U10),MAX(0,MIN($G10,$G10/10*$U10)),IF(OR(NOT(ISNUMBER($M10)),$M10<=0,$Q10="",NOT(OR($W10="OK",$W10="FILE LINK (check)"))),"",IF($G10<=$M10+5,$G10,$M10))))) | L10: =IF($B10="","",1) | N10: =IF($B10="","",IF($G10="","",IF(ISNUMBER($M10),$M10,0)-$G10)) | W10: =IF($B10="","",IF($Q10="","MISSING LINK",IF(NOT(ISNUMBER(SEARCH("drive.google.com",$Q10))),"NOT DRIVE LINK",IFERROR(IF(ISNUMBER(SEARCH(MID(Summary!$N$3,SEARCH("/folders/",Summary!$N$3)+9,SEARCH("?",Summary!$N$3&"?")-(SEARCH("/folders/",Summary!$N$3)+9)),$Q10)),"OK",IF(ISNUMBER(SEARCH("/file/d/",$Q10)),"FILE LINK (check)","WRONG DRIVE")),"WRONG DRIVE")))) | X10: =IF(OR($B10=2001,$B10=2002),IF(OR(LEN(TRIM($R10))=0,LEN(TRIM($S10))=0),"",TRIM($R10)&" | "&TRIM($S10)),"") | Y10: =IF($X10="","",COUNTIF($X$2:$X$1500,$X10)) | Z10: =IF($X10="","",COUNTIF($X$2:$X10,$X10)) | AA10: =IF(AND($X10<>"",$Y10>=3,$Z10=1),COUNTIF($AA$1:AA9,">0")+1,"")
C11: =IF($B11="","",1) | D11: =IF($B11="","",IFERROR(VLOOKUP($B11,'Task library'!$A:$E,2,FALSE()),"")) | E11: =IF($B11="","",IFERROR(VLOOKUP($B11,'Task library'!$A:$E,3,FALSE()),"")) | F11: =IF($B11="","",IFERROR(VLOOKUP($B11,'Task library'!$A:$E,4,FALSE()),"")) | H11: =IF(OR($B11="",$I11=""),"",IFERROR($I11-$G11,"")) | I11: =IF($B11="","",IF($G11="","",IF(ISNUMBER($U11),MAX(0,MIN($G11,$G11/10*$U11)),IF(OR(NOT(ISNUMBER($M11)),$M11<=0,$Q11="",NOT(OR($W11="OK",$W11="FILE LINK (check)"))),"",IF($G11<=$M11+5,$G11,$M11))))) | L11: =IF($B11="","",1) | N11: =IF($B11="","",IF($G11="","",IF(ISNUMBER($M11),$M11,0)-$G11)) | W11: =IF($B11="","",IF($Q11="","MISSING LINK",IF(NOT(ISNUMBER(SEARCH("drive.google.com",$Q11))),"NOT DRIVE LINK",IFERROR(IF(ISNUMBER(SEARCH(MID(Summary!$N$3,SEARCH("/folders/",Summary!$N$3)+9,SEARCH("?",Summary!$N$3&"?")-(SEARCH("/folders/",Summary!$N$3)+9)),$Q11)),"OK",IF(ISNUMBER(SEARCH("/file/d/",$Q11)),"FILE LINK (check)","WRONG DRIVE")),"WRONG DRIVE")))) | X11: =IF(OR($B11=2001,$B11=2002),IF(OR(LEN(TRIM($R11))=0,LEN(TRIM($S11))=0),"",TRIM($R11)&" | "&TRIM($S11)),"") | Y11: =IF($X11="","",COUNTIF($X$2:$X$1500,$X11)) | Z11: =IF($X11="","",COUNTIF($X$2:$X11,$X11)) | AA11: =IF(AND($X11<>"",$Y11>=3,$Z11=1),COUNTIF($AA$1:AA10,">0")+1,"")
C12: =IF($B12="","",1) | D12: =IF($B12="","",IFERROR(VLOOKUP($B12,'Task library'!$A:$E,2,FALSE()),"")) | E12: =IF($B12="","",IFERROR(VLOOKUP($B12,'Task library'!$A:$E,3,FALSE()),"")) | F12: =IF($B12="","",IFERROR(VLOOKUP($B12,'Task library'!$A:$E,4,FALSE()),"")) | H12: =IF(OR($B12="",$I12=""),"",IFERROR($I12-$G12,"")) | I12: =IF($B12="","",IF($G12="","",IF(ISNUMBER($U12),MAX(0,MIN($G12,$G12/10*$U12)),IF(OR(NOT(ISNUMBER($M12)),$M12<=0,$Q12="",NOT(OR($W12="OK",$W12="FILE LINK (check)"))),"",IF($G12<=$M12+5,$G12,$M12))))) | L12: =IF($B12="","",1) | N12: =IF($B12="","",IF($G12="","",IF(ISNUMBER($M12),$M12,0)-$G12)) | W12: =IF($B12="","",IF($Q12="","MISSING LINK",IF(NOT(ISNUMBER(SEARCH("drive.google.com",$Q12))),"NOT DRIVE LINK",IFERROR(IF(ISNUMBER(SEARCH(MID(Summary!$N$3,SEARCH("/folders/",Summary!$N$3)+9,SEARCH("?",Summary!$N$3&"?")-(SEARCH("/folders/",Summary!$N$3)+9)),$Q12)),"OK",IF(ISNUMBER(SEARCH("/file/d/",$Q12)),"FILE LINK (check)","WRONG DRIVE")),"WRONG DRIVE")))) | X12: =IF(OR($B12=2001,$B12=2002),IF(OR(LEN(TRIM($R12))=0,LEN(TRIM($S12))=0),"",TRIM($R12)&" | "&TRIM($S12)),"") | Y12: =IF($X12="","",COUNTIF($X$2:$X$1500,$X12)) | Z12: =IF($X12="","",COUNTIF($X$2:$X12,$X12)) | AA12: =IF(AND($X12<>"",$Y12>=3,$Z12=1),COUNTIF($AA$1:AA11,">0")+1,"")
C13: =IF($B13="","",1) | D13: =IF($B13="","",IFERROR(VLOOKUP($B13,'Task library'!$A:$E,2,FALSE()),"")) | E13: =IF($B13="","",IFERROR(VLOOKUP($B13,'Task library'!$A:$E,3,FALSE()),"")) | F13: =IF($B13="","",IFERROR(VLOOKUP($B13,'Task library'!$A:$E,4,FALSE()),"")) | H13: =IF(OR($B13="",$I13=""),"",IFERROR($I13-$G13,"")) | I13: =IF($B13="","",IF($G13="","",IF(ISNUMBER($U13),MAX(0,MIN($G13,$G13/10*$U13)),IF(OR(NOT(ISNUMBER($M13)),$M13<=0,$Q13="",NOT(OR($W13="OK",$W13="FILE LINK (check)"))),"",IF($G13<=$M13+5,$G13,$M13))))) | L13: =IF($B13="","",1) | N13: =IF($B13="","",IF($G13="","",IF(ISNUMBER($M13),$M13,0)-$G13)) | W13: =IF($B13="","",IF($Q13="","MISSING LINK",IF(NOT(ISNUMBER(SEARCH("drive.google.com",$Q13))),"NOT DRIVE LINK",IFERROR(IF(ISNUMBER(SEARCH(MID(Summary!$N$3,SEARCH("/folders/",Summary!$N$3)+9,SEARCH("?",Summary!$N$3&"?")-(SEARCH("/folders/",Summary!$N$3)+9)),$Q13)),"OK",IF(ISNUMBER(SEARCH("/file/d/",$Q13)),"FILE LINK (check)","WRONG DRIVE")),"WRONG DRIVE")))) | X13: =IF(OR($B13=2001,$B13=2002),IF(OR(LEN(TRIM($R13))=0,LEN(TRIM($S13))=0),"",TRIM($R13)&" | "&TRIM($S13)),"") | Y13: =IF($X13="","",COUNTIF($X$2:$X$1500,$X13)) | Z13: =IF($X13="","",COUNTIF($X$2:$X13,$X13)) | AA13: =IF(AND($X13<>"",$Y13>=3,$Z13=1),COUNTIF($AA$1:AA12,">0")+1,"")
... C1500: =IF($B1500="","",1) | D1500: =IF($B1500="","",IFERROR(VLOOKUP($B1500,'Task library'!$A:$E,2,FALSE()),"")) | E1500: =IF($B1500="","",IFERROR(VLOOKUP($B1500,'Task library'!$A:$E,3,FALSE()),"")) | F1500: =IF($B1500="","",IFERROR(VLOOKUP($B1500,'Task library'!$A:$E,4,FALSE()),"")) | H1500: =IF(OR($B1500="",$I1500=""),"",IFERROR($I1500-$G1500,"")) | I1500: =IF($B1500="","",IF($G1500="","",IF(ISNUMBER($U1500),MAX(0,MIN($G1500,$G1500/10*$U1500)),IF(OR(NOT(ISNUMBER($M1500)),$M1500<=0,$Q1500="",NOT(OR($W1500="OK",$W1500="FILE LINK (check)"))),"",IF($G1500<=$M1500+5,$G1500,$M1500))))) | L1500: =IF($B1500="","",1) | N1500: =IF($B1500="","",IF($G1500="","",IF(ISNUMBER($M1500),$M1500,0)-$G1500)) | W1500: =IF($B1500="","",IF($Q1500="","MISSING LINK",IF(NOT(ISNUMBER(SEARCH("drive.google.com",$Q1500))),"NOT DRIVE LINK",IFERROR(IF(ISNUMBER(SEARCH(MID(Summary!$N$3,SEARCH("/folders/",Summary!$N$3)+9,SEARCH("?",Summary!$N$3&"?")-(SEARCH("/folders/",Summary!$N$3)+9)),$Q1500)),"OK",IF(ISNUMBER(SEARCH("/file/d/",$Q1500)),"FILE LINK (check)","WRONG DRIVE")),"WRONG DRIVE")))) | X1500: =IF(OR($B1500=2001,$B1500=2002),IF(OR(LEN(TRIM($R1500))=0,LEN(TRIM($S1500))=0),"",TRIM($R1500)&" | "&TRIM($S1500)),"") | Y1500: =IF($X1500="","",COUNTIF($X$2:$X$1500,$X1500)) | Z1500: =IF($X1500="","",COUNTIF($X$2:$X1500,$X1500)) | AA1500: =IF(AND($X1500<>"",$Y1500>=3,$Z1500=1),COUNTIF($AA$1:AA1499,">0")+1,"")

Sheet Office time approval
A1: Date | B1: Start work 1 | C1: Start lunch | D1: Start work 2 | E1: Start afternoon break | F1: Start work 3 | G1: End workday | H1: Work report total (min) | I1: Actual worked (min) | J1: Delta (min) | K1: Explanation of delta | L1: Approval status | M1: Approved delta -> Summary C (min)
A2: {=IFERROR(INDEX(_xlfn.UNIQUE(_xlfn._xlws.FILTER('Work report'!$A$2:$A$1500,'Work report'!$B$2:$B$1500<>"")),ROW(A1)),"")} | H2: =IF($A2="","",SUMIFS('Work report'!$I$2:$I$1500,'Work report'!$A$2:$A$1500,$A2,'Work report'!$B$2:$B$1500,"<>")) | I2: =IF( SUM( IF(AND($B2<>"",$C2<>""),($C2-$B2)*1440,0), IF(AND($D2<>"",$E2<>""),($E2-$D2)*1440,0), IF(AND($F2<>"",$G2<>""),($G2-$F2)*1440,0) )=0, "", SUM( IF(AND($B2<>"",$C2<>""),($C2-$B2)*1440,0), IF(AND($D2<>"",$E2<>""),($E2-$D2)*1440,0), IF(AND($F2<>"",$G2<>""),($G2-$F2)*1440,0) ) ) | J2: =IF(OR($H2="",$I2=""),"",$I2-$H2) | M2: =IF(OR($J2="",$L2<>"Approved"),"",$J2)
A3: {=IFERROR(INDEX(_xlfn.UNIQUE(_xlfn._xlws.FILTER('Work report'!$A$2:$A$1500,'Work report'!$B$2:$B$1500<>"")),ROW(A2)),"")} | H3: =IF($A3="","",SUMIFS('Work report'!$I$2:$I$1500,'Work report'!$A$2:$A$1500,$A3,'Work report'!$B$2:$B$1500,"<>")) | I3: =IF( SUM( IF(AND($B3<>"",$C3<>""),($C3-$B3)*1440,0), IF(AND($D3<>"",$E3<>""),($E3-$D3)*1440,0), IF(AND($F3<>"",$G3<>""),($G3-$F3)*1440,0) )=0, "", SUM( IF(AND($B3<>"",$C3<>""),($C3-$B3)*1440,0), IF(AND($D3<>"",$E3<>""),($E3-$D3)*1440,0), IF(AND($F3<>"",$G3<>""),($G3-$F3)*1440,0) ) ) | J3: =IF(OR($H3="",$I3=""),"",$I3-$H3) | M3: =IF(OR($J3="",$L3<>"Approved"),"",$J3)
A4: {=IFERROR(INDEX(_xlfn.UNIQUE(_xlfn._xlws.FILTER('Work report'!$A$2:$A$1500,'Work report'!$B$2:$B$1500<>"")),ROW(A3)),"")} | H4: =IF($A4="","",SUMIFS('Work report'!$I$2:$I$1500,'Work report'!$A$2:$A$1500,$A4,'Work report'!$B$2:$B$1500,"<>")) | I4: =IF( SUM( IF(AND($B4<>"",$C4<>""),($C4-$B4)*1440,0), IF(AND($D4<>"",$E4<>""),($E4-$D4)*1440,0), IF(AND($F4<>"",$G4<>""),($G4-$F4)*1440,0) )=0, "", SUM( IF(AND($B4<>"",$C4<>""),($C4-$B4)*1440,0), IF(AND($D4<>"",$E4<>""),($E4-$D4)*1440,0), IF(AND($F4<>"",$G4<>""),($G4-$F4)*1440,0) ) ) | J4: =IF(OR($H4="",$I4=""),"",$I4-$H4) | M4: =IF(OR($J4="",$L4<>"Approved"),"",$J4)
A5: {=IFERROR(INDEX(_xlfn.UNIQUE(_xlfn._xlws.FILTER('Work report'!$A$2:$A$1500,'Work report'!$B$2:$B$1500<>"")),ROW(A4)),"")} | H5: =IF($A5="","",SUMIFS('Work report'!$I$2:$I$1500,'Work report'!$A$2:$A$1500,$A5,'Work report'!$B$2:$B$1500,"<>")) | I5: =IF( SUM( IF(AND($B5<>"",$C5<>""),($C5-$B5)*1440,0), IF(AND($D5<>"",$E5<>""),($E5-$D5)*1440,0), IF(AND($F5<>"",$G5<>""),($G5-$F5)*1440,0) )=0, "", SUM( IF(AND($B5<>"",$C5<>""),($C5-$B5)*1440,0), IF(AND($D5<>"",$E5<>""),($E5-$D5)*1440,0), IF(AND($F5<>"",$G5<>""),($G5-$F5)*1440,0) ) ) | J5: =IF(OR($H5="",$I5=""),"",$I5-$H5) | M5: =IF(OR($J5="",$L5<>"Approved"),"",$J5)
A6: {=IFERROR(INDEX(_xlfn.UNIQUE(_xlfn._xlws.FILTER('Work report'!$A$2:$A$1500,'Work report'!$B$2:$B$1500<>"")),ROW(A5)),"")} | H6: =IF($A6="","",SUMIFS('Work report'!$I$2:$I$1500,'Work report'!$A$2:$A$1500,$A6,'Work report'!$B$2:$B$1500,"<>")) | I6: =IF( SUM( IF(AND($B6<>"",$C6<>""),($C6-$B6)*1440,0), IF(AND($D6<>"",$E6<>""),($E6-$D6)*1440,0), IF(AND($F6<>"",$G6<>""),($G6-$F6)*1440,0) )=0, "", SUM( IF(AND($B6<>"",$C6<>""),($C6-$B6)*1440,0), IF(AND($D6<>"",$E6<>""),($E6-$D6)*1440,0), IF(AND($F6<>"",$G6<>""),($G6-$F6)*1440,0) ) ) | J6: =IF(OR($H6="",$I6=""),"",$I6-$H6) | M6: =IF(OR($J6="",$L6<>"Approved"),"",$J6)
A7: {=IFERROR(INDEX(_xlfn.UNIQUE(_xlfn._xlws.FILTER('Work report'!$A$2:$A$1500,'Work report'!$B$2:$B$1500<>"")),ROW(A6)),"")} | H7: =IF($A7="","",SUMIFS('Work report'!$I$2:$I$1500,'Work report'!$A$2:$A$1500,$A7,'Work report'!$B$2:$B$1500,"<>")) | I7: =IF( SUM( IF(AND($B7<>"",$C7<>""),($C7-$B7)*1440,0), IF(AND($D7<>"",$E7<>""),($E7-$D7)*1440,0), IF(AND($F7<>"",$G7<>""),($G7-$F7)*1440,0) )=0, "", SUM( IF(AND($B7<>"",$C7<>""),($C7-$B7)*1440,0), IF(AND($D7<>"",$E7<>""),($E7-$D7)*1440,0), IF(AND($F7<>"",$G7<>""),($G7-$F7)*1440,0) ) ) | J7: =IF(OR($H7="",$I7=""),"",$I7-$H7) | M7: =IF(OR($J7="",$L7<>"Approved"),"",$J7)
A8: {=IFERROR(INDEX(_xlfn.UNIQUE(_xlfn._xlws.FILTER('Work report'!$A$2:$A$1500,'Work report'!$B$2:$B$1500<>"")),ROW(A7)),"")} | H8: =IF($A8="","",SUMIFS('Work report'!$I$2:$I$1500,'Work report'!$A$2:$A$1500,$A8,'Work report'!$B$2:$B$1500,"<>")) | I8: =IF( SUM( IF(AND($B8<>"",$C8<>""),($C8-$B8)*1440,0), IF(AND($D8<>"",$E8<>""),($E8-$D8)*1440,0), IF(AND($F8<>"",$G8<>""),($G8-$F8)*1440,0) )=0, "", SUM( IF(AND($B8<>"",$C8<>""),($C8-$B8)*1440,0), IF(AND($D8<>"",$E8<>""),($E8-$D8)*1440,0), IF(AND($F8<>"",$G8<>""),($G8-$F8)*1440,0) ) ) | J8: =IF(OR($H8="",$I8=""),"",$I8-$H8) | M8: =IF(OR($J8="",$L8<>"Approved"),"",$J8)
A9: {=IFERROR(INDEX(_xlfn.UNIQUE(_xlfn._xlws.FILTER('Work report'!$A$2:$A$1500,'Work report'!$B$2:$B$1500<>"")),ROW(A8)),"")} | H9: =IF($A9="","",SUMIFS('Work report'!$I$2:$I$1500,'Work report'!$A$2:$A$1500,$A9,'Work report'!$B$2:$B$1500,"<>")) | I9: =IF( SUM( IF(AND($B9<>"",$C9<>""),($C9-$B9)*1440,0), IF(AND($D9<>"",$E9<>""),($E9-$D9)*1440,0), IF(AND($F9<>"",$G9<>""),($G9-$F9)*1440,0) )=0, "", SUM( IF(AND($B9<>"",$C9<>""),($C9-$B9)*1440,0), IF(AND($D9<>"",$E9<>""),($E9-$D9)*1440,0), IF(AND($F9<>"",$G9<>""),($G9-$F9)*1440,0) ) ) | J9: =IF(OR($H9="",$I9=""),"",$I9-$H9) | M9: =IF(OR($J9="",$L9<>"Approved"),"",$J9)
A10: {=IFERROR(INDEX(_xlfn.UNIQUE(_xlfn._xlws.FILTER('Work report'!$A$2:$A$1500,'Work report'!$B$2:$B$1500<>"")),ROW(A9)),"")} | H10: =IF($A10="","",SUMIFS('Work report'!$I$2:$I$1500,'Work report'!$A$2:$A$1500,$A10,'Work report'!$B$2:$B$1500,"<>")) | I10: =IF( SUM( IF(AND($B10<>"",$C10<>""),($C10-$B10)*1440,0), IF(AND($D10<>"",$E10<>""),($E10-$D10)*1440,0), IF(AND($F10<>"",$G10<>""),($G10-$F10)*1440,0) )=0, "", SUM( IF(AND($B10<>"",$C10<>""),($C10-$B10)*1440,0), IF(AND($D10<>"",$E10<>""),($E10-$D10)*1440,0), IF(AND($F10<>"",$G10<>""),($G10-$F10)*1440,0) ) ) | J10: =IF(OR($H10="",$I10=""),"",$I10-$H10) | M10: =IF(OR($J10="",$L10<>"Approved"),"",$J10)
A11: {=IFERROR(INDEX(_xlfn.UNIQUE(_xlfn._xlws.FILTER('Work report'!$A$2:$A$1500,'Work report'!$B$2:$B$1500<>"")),ROW(A10)),"")} | H11: =IF($A11="","",SUMIFS('Work report'!$I$2:$I$1500,'Work report'!$A$2:$A$1500,$A11,'Work report'!$B$2:$B$1500,"<>")) | I11: =IF( SUM( IF(AND($B11<>"",$C11<>""),($C11-$B11)*1440,0), IF(AND($D11<>"",$E11<>""),($E11-$D11)*1440,0), IF(AND($F11<>"",$G11<>""),($G11-$F11)*1440,0) )=0, "", SUM( IF(AND($B11<>"",$C11<>""),($C11-$B11)*1440,0), IF(AND($D11<>"",$E11<>""),($E11-$D11)*1440,0), IF(AND($F11<>"",$G11<>""),($G11-$F11)*1440,0) ) ) | J11: =IF(OR($H11="",$I11=""),"",$I11-$H11) | M11: =IF(OR($J11="",$L11<>"Approved"),"",$J11)
A12: {=IFERROR(INDEX(_xlfn.UNIQUE(_xlfn._xlws.FILTER('Work report'!$A$2:$A$1500,'Work report'!$B$2:$B$1500<>"")),ROW(A11)),"")} | H12: =IF($A12="","",SUMIFS('Work report'!$I$2:$I$1500,'Work report'!$A$2:$A$1500,$A12,'Work report'!$B$2:$B$1500,"<>")) | I12: =IF( SUM( IF(AND($B12<>"",$C12<>""),($C12-$B12)*1440,0), IF(AND($D12<>"",$E12<>""),($E12-$D12)*1440,0), IF(AND($F12<>"",$G12<>""),($G12-$F12)*1440,0) )=0, "", SUM( IF(AND($B12<>"",$C12<>""),($C12-$B12)*1440,0), IF(AND($D12<>"",$E12<>""),($E12-$D12)*1440,0), IF(AND($F12<>"",$G12<>""),($G12-$F12)*1440,0) ) ) | J12: =IF(OR($H12="",$I12=""),"",$I12-$H12) | M12: =IF(OR($J12="",$L12<>"Approved"),"",$J12)
A13: {=IFERROR(INDEX(_xlfn.UNIQUE(_xlfn._xlws.FILTER('Work report'!$A$2:$A$1500,'Work report'!$B$2:$B$1500<>"")),ROW(A12)),"")} | H13: =IF($A13="","",SUMIFS('Work report'!$I$2:$I$1500,'Work report'!$A$2:$A$1500,$A13,'Work report'!$B$2:$B$1500,"<>")) | I13: =IF( SUM( IF(AND($B13<>"",$C13<>""),($C13-$B13)*1440,0), IF(AND($D13<>"",$E13<>""),($E13-$D13)*1440,0), IF(AND($F13<>"",$G13<>""),($G13-$F13)*1440,0) )=0, "", SUM( IF(AND($B13<>"",$C13<>""),($C13-$B13)*1440,0), IF(AND($D13<>"",$E13<>""),($E13-$D13)*1440,0), IF(AND($F13<>"",$G13<>""),($G13-$F13)*1440,0) ) ) | J13: =IF(OR($H13="",$I13=""),"",$I13-$H13) | M13: =IF(OR($J13="",$L13<>"Approved"),"",$J13)
... A1500: {=IFERROR(INDEX(_xlfn.UNIQUE(_xlfn._xlws.FILTER('Work report'!$A$2:$A$1500,'Work report'!$B$2:$B$1500<>"")),ROW(A1499)),"")} | H1500: =IF($A1500="","",SUMIFS('Work report'!$I$2:$I$1500,'Work report'!$A$2:$A$1500,$A1500,'Work report'!$B$2:$B$1500,"<>")) | I1500: =IF( SUM( IF(AND($B1500<>"",$C1500<>""),($C1500-$B1500)*1440,0), IF(AND($D1500<>"",$E1500<>""),($E1500-$D1500)*1440,0), IF(AND($F1500<>"",$G1500<>""),($G1500-$F1500)*1440,0) )=0, "", SUM( IF(AND($B1500<>"",$C1500<>""),($C1500-$B1500)*1440,0), IF(AND($D1500<>"",$E1500<>""),($E1500-$D1500)*1440,0), IF(AND($F1500<>"",$G1500<>""),($G1500-$F1500)*1440,0) ) ) | J1500: =IF(OR($H1500="",$I1500=""),"",$I1500-$H1500) | M1500: =IF(OR($J1500="",$L1500<>"Approved"),"",$J1500)

Sheet Task library
A1: No | B1: Task name | C1: Description | D1: Std time (min) | E1: Link template | F1: Note1 | G1: Note2
A2: DEV01 | B2: Tiếp nhận yêu cầu | C2: Nhận yêu cầu từ khách hàng, chủ doanh nghiệp hoặc bộ phận nội bộ | D2: 1 | F2: for Dev
A3: DEV02 | B3: Làm rõ yêu cầu | C3: Hỏi lại những điểm chưa rõ, xác định mục tiêu thật sự của chức năng/dự án | D3: 1 | F3: for Dev
A4: DEV03 | B4: Phân tích nghiệp vụ | C4: Chuyển yêu cầu kinh doanh thành yêu cầu kỹ thuật dễ hiểu cho lập trình viên | D4: 1 | F4: for Dev
A5: DEV04 | B5: Xác định phạm vi công việc | C5: Chốt việc nào làm, việc nào chưa làm, tránh mở rộng ngoài kế hoạch | D5: 1 | F5: for Dev
A6: DEV05 | B6: Chia nhỏ task | C6: Tách dự án lớn thành các đầu việc nhỏ, rõ ràng, có thể giao cho từng người | D6: 1 | F6: for Dev
A7: DEV06 | B7: Ước lượng thời gian | C7: Dự tính thời gian hoàn thành từng task, xác định việc gấp và việc có thể để sau | D7: 1 | F7: for Dev
A8: DEV07 | B8: Phân công công việc | C8: Giao task cho lập trình viên phù hợp với năng lực, kinh nghiệm và thời gian | D8: 1 | F8: for Dev
A9: DEV08 | B9: Theo dõi tiến độ | C9: Kiểm tra task đang làm, task bị kẹt, task đã xong, task cần hỗ trợ | D9: 1 | F9: for Dev
A10: DEV09 | B10: Kiểm tra chất lượng đầu ra | C10: Xem chức năng có chạy đúng, giao diện có ổn, dữ liệu có chính xác không | D10: 1 | F10: for Dev
A11: DEV10 | B11: Review logic / giải pháp | C11: Kiểm tra cách làm của lập trình viên có hợp lý, bền vững và dễ bảo trì không | D11: 1 | F11: for Dev
A12: DEV11 | B12: Kiểm soát lỗi phát sinh | C12: Theo dõi bug, phân loại mức độ nghiêm trọng và giao người xử lý | D12: 1 | F12: for Dev
A13: DEV12 | B13: Ưu tiên công việc | C13: Sắp xếp thứ tự xử lý: lỗi nghiêm trọng, khách đang chờ, việc ảnh hưởng doanh thu | D13: 1 | F13: for Dev
... A21: DEV20 | B21: Chuẩn hóa quy trình làm việc | C21: Xây dựng quy tắc đặt task, ghi log, quay video, nghiệm thu, bàn giao và lưu tài liệu | D21: 1 | F21: for Dev
A22: DTL01 | B22: Tiếp nhận và làm rõ yêu cầu | C22: Đọc yêu cầu từ anh, khách hàng hoặc nội bộ; hỏi lại điểm chưa rõ; xác định mục tiêu thật sự của công việc | D22: 1 | F22: for IT Team Lead | G22: Tin nhắn, email, tài liệu yêu cầu, ghi chú phân tích
A23: DTL02 | B23: Phân tích yêu cầu thành task kỹ thuật | C23: Chuyển yêu cầu chung thành các task nhỏ cho lập trình viên: frontend, backend, database, API, deploy, test | D23: 1 | F23: for IT Team Lead | G23: File/task list, ảnh chụp task, link Trello/Drive/Excel
A24: DTL03 | B24: Lập kế hoạch triển khai | C24: Xác định thứ tự làm việc, thời gian dự kiến, người phụ trách, rủi ro và mốc kiểm tra | D24: 1 | F24: for IT Team Lead | G24: Kế hoạch ngắn, bảng phân công, ghi chú trong Work list
A25: DTL04 | B25: Phân công việc cho lập trình viên | C25: Giao task đúng người, đúng năng lực; ghi rõ yêu cầu, deadline, kết quả cần bàn giao | D25: 1 | F25: for IT Team Lead | G25: Tin nhắn giao việc, task trong hệ thống, Work list
A26: DTL05 | B26: Theo dõi tiến độ nhóm lập trình | C26: Kiểm tra ai đang làm gì, task nào xong, task nào bị kẹt, task nào cần ưu tiên | D26: 1 | F26: for IT Team Lead | G26: Báo cáo tiến độ, ảnh chụp bảng task, ghi chú follow-up
A27: DTL06 | B27: Hỗ trợ lập trình viên khi bị kẹt | C27: Hướng dẫn cách debug, tìm nguyên nhân lỗi, gợi ý phương án xử lý hoặc chia nhỏ vấn đề | D27: 1 | F27: for IT Team Lead | G27: Video trao đổi, ghi chú hướng xử lý, đoạn code/log liên quan
A28: DTL07 | B28: Review code và logic xử lý | C28: Kiểm tra code của lập trình viên: logic, bảo mật, dễ bảo trì, tránh sửa tạm gây lỗi sau này | D28: 1 | F28: for IT Team Lead | G28: Pull request, ảnh code, ghi chú review, video review
A29: DTL08 | B29: Kiểm tra chức năng sau khi lập trình viên hoàn thành | C29: Test lại chức năng: nhập dữ liệu, bấm nút, kiểm tra kết quả, kiểm tra lỗi trên desktop/mobile | D29: 1 | F29: for IT Team Lead | G29: Video test, ảnh trước/sau, link trang đã sửa
A30: DTL09 | B30: Kiểm soát lỗi phát sinh / bug tracking | C30: Ghi nhận lỗi, phân loại mức độ nghiêm trọng, giao người sửa và kiểm tra lại sau khi sửa | D30: 1 | F30: for IT Team Lead | G30: Danh sách bug, ảnh lỗi, video lỗi, ghi chú kết quả sửa
A31: DTL10 | B31: Quản lý deploy / cập nhật lên server | C31: Kiểm tra điều kiện trước khi đưa code lên live; hạn chế deploy vội gây lỗi website đang chạy | D31: 1 | F31: for IT Team Lead | G31: Video deploy, log deploy, ghi chú version, link trang sau deploy
A32: DTL11 | B32: Kiểm tra sau deploy | C32: Sau khi cập nhật lên server, kiểm tra website/app có hoạt động bình thường không: giao diện, form, menu, đặt bàn, đặt món, chatbot... | D32: 1 | F32: for IT Team Lead | G32: Video test live, ảnh chụp trang live, checklist sau deploy
A33: DTL12 | B33: Quản lý database / migration quan trọng | C33: Kiểm tra thay đổi database, migration, backup trước khi sửa dữ liệu quan trọng | D33: 1 | F33: for IT Team Lead | G33: File migration, ảnh database, log backup, video thao tác
... A39: DTL18 | B39: Kiểm tra bằng chứng công việc của lập trình viên | C39: Xem video, link Drive, mô tả task, thời lượng, kết quả thực tế để đánh giá công việc có hợp lệ không | D39: 1 | F39: for IT Team Lead | G39: Link video, Work report, ghi chú đánh giá, điểm review
A40: 1001 | B40: Học & Tìm hiểu | C40: Học / tìm hiểu quy trình – tài liệu | D40: 1 | F40: other
A41: 2001 | B41: Việc mới | C41: Tất cả những việc chưa có trên hệ thống | D41: 1 | F41: other
A42: 2002 | B42: Task dự phòng | C42: Tạm thời ko dùng Task dự phòng này | D42: 1 | F42: other

Sheet Missing tasks auto 
A1: Date | B1: Employee | C1: Task name | D1: Description | E1: Quantity | F1: Time allotted for the task (min) | G1: Video link (Google Drive) | H1: Video duration (min) | I1: Date recorded | J1: Approved time + Bonus time | K1: Manual task name | L1: Manual description | M1: Reason / Note | N1: Status | O1: Final task name | P1: Final description | Q1: Source
A2: =IF($C2="","",IFERROR(INDEX('Work report'!$A$2:$A$1500,MATCH(ROWS($C$2:C2),'Work report'!$AA$2:$AA$1500,0)),"")) | B2: =IF($C2="","",Setup!$B$4) | C2: =IFERROR(INDEX('Work report'!$R$2:$R$1500,MATCH(ROWS($C$2:C2),'Work report'!$AA$2:$AA$1500,0)),"") | D2: =IFERROR(INDEX('Work report'!$S$2:$S$1500,MATCH(ROWS($D$2:D2),'Work report'!$AA$2:$AA$1500,0)),"") | E2: =IF($C2="","",IFERROR(INDEX('Work report'!$C$2:$C$1500,MATCH(ROWS($C$2:C2),'Work report'!$AA$2:$AA$1500,0)),"")) | F2: =IF($C2="","",IFERROR(INDEX('Work report'!$F$2:$F$1500,MATCH(ROWS($C$2:C2),'Work report'!$AA$2:$AA$1500,0)),"")) | G2: =IF($C2="","",IFERROR(HYPERLINK(INDEX('Work report'!$Q$2:$Q$1500,MATCH(ROWS($C$2:C2),'Work report'!$AA$2:$AA$1500,0)),INDEX('Work report'!$Q$2:$Q$1500,MATCH(ROWS($C$2:C2),'Work report'!$AA$2:$AA$1500,0))),"")) | H2: =IF($C2="","",IFERROR(INDEX('Work report'!$M$2:$M$1500,MATCH(ROWS($C$2:C2),'Work report'!$AA$2:$AA$1500,0)),"")) | I2: =IF($C2="","",IFERROR(INDEX('Work report'!$A$2:$A$1500,MATCH(ROWS($C$2:C2),'Work report'!$AA$2:$AA$1500,0)),"")) | J2: =IF($C2="","",IFERROR(INDEX('Work report'!$I$2:$I$1500,MATCH(ROWS($C$2:C2),'Work report'!$AA$2:$AA$1500,0)),"")) | O2: =IF($C2<>"",$C2,$K2) -> 0 | P2: =IF($D2<>"",$D2,$L2) -> 0 | Q2: =IF($C2<>"","System",IF($K2<>"","Manual",""))
A3: =IF($C3="","",IFERROR(INDEX('Work report'!$A$2:$A$1500,MATCH(ROWS($C$2:C3),'Work report'!$AA$2:$AA$1500,0)),"")) | B3: =IF($C3="","",Setup!$B$4) | C3: =IFERROR(INDEX('Work report'!$R$2:$R$1500,MATCH(ROWS($C$2:C3),'Work report'!$AA$2:$AA$1500,0)),"") | D3: =IFERROR(INDEX('Work report'!$S$2:$S$1500,MATCH(ROWS($D$2:D3),'Work report'!$AA$2:$AA$1500,0)),"") | E3: =IF($C3="","",IFERROR(INDEX('Work report'!$C$2:$C$1500,MATCH(ROWS($C$2:C3),'Work report'!$AA$2:$AA$1500,0)),"")) | F3: =IF($C3="","",IFERROR(INDEX('Work report'!$F$2:$F$1500,MATCH(ROWS($C$2:C3),'Work report'!$AA$2:$AA$1500,0)),"")) | G3: =IF($C3="","",IFERROR(HYPERLINK(INDEX('Work report'!$Q$2:$Q$1500,MATCH(ROWS($C$2:C3),'Work report'!$AA$2:$AA$1500,0)),INDEX('Work report'!$Q$2:$Q$1500,MATCH(ROWS($C$2:C3),'Work report'!$AA$2:$AA$1500,0))),"")) | H3: =IF($C3="","",IFERROR(INDEX('Work report'!$M$2:$M$1500,MATCH(ROWS($C$2:C3),'Work report'!$AA$2:$AA$1500,0)),"")) | I3: =IF($C3="","",IFERROR(INDEX('Work report'!$A$2:$A$1500,MATCH(ROWS($C$2:C3),'Work report'!$AA$2:$AA$1500,0)),"")) | J3: =IF($C3="","",IFERROR(INDEX('Work report'!$I$2:$I$1500,MATCH(ROWS($C$2:C3),'Work report'!$AA$2:$AA$1500,0)),"")) | O3: =IF($C3<>"",$C3,$K3) -> 0 | P3: =IF($D3<>"",$D3,$L3) -> 0 | Q3: =IF($C3<>"","System",IF($K3<>"","Manual",""))
A4: =IF($C4="","",IFERROR(INDEX('Work report'!$A$2:$A$1500,MATCH(ROWS($C$2:C4),'Work report'!$AA$2:$AA$1500,0)),"")) | B4: =IF($C4="","",Setup!$B$4) | C4: =IFERROR(INDEX('Work report'!$R$2:$R$1500,MATCH(ROWS($C$2:C4),'Work report'!$AA$2:$AA$1500,0)),"") | D4: =IFERROR(INDEX('Work report'!$S$2:$S$1500,MATCH(ROWS($D$2:D4),'Work report'!$AA$2:$AA$1500,0)),"") | E4: =IF($C4="","",IFERROR(INDEX('Work report'!$C$2:$C$1500,MATCH(ROWS($C$2:C4),'Work report'!$AA$2:$AA$1500,0)),"")) | F4: =IF($C4="","",IFERROR(INDEX('Work report'!$F$2:$F$1500,MATCH(ROWS($C$2:C4),'Work report'!$AA$2:$AA$1500,0)),"")) | G4: =IF($C4="","",IFERROR(HYPERLINK(INDEX('Work report'!$Q$2:$Q$1500,MATCH(ROWS($C$2:C4),'Work report'!$AA$2:$AA$1500,0)),INDEX('Work report'!$Q$2:$Q$1500,MATCH(ROWS($C$2:C4),'Work report'!$AA$2:$AA$1500,0))),"")) | H4: =IF($C4="","",IFERROR(INDEX('Work report'!$M$2:$M$1500,MATCH(ROWS($C$2:C4),'Work report'!$AA$2:$AA$1500,0)),"")) | I4: =IF($C4="","",IFERROR(INDEX('Work report'!$A$2:$A$1500,MATCH(ROWS($C$2:C4),'Work report'!$AA$2:$AA$1500,0)),"")) | J4: =IF($C4="","",IFERROR(INDEX('Work report'!$I$2:$I$1500,MATCH(ROWS($C$2:C4),'Work report'!$AA$2:$AA$1500,0)),"")) | O4: =IF($C4<>"",$C4,$K4) -> 0 | P4: =IF($D4<>"",$D4,$L4) -> 0 | Q4: =IF($C4<>"","System",IF($K4<>"","Manual",""))
A5: =IF($C5="","",IFERROR(INDEX('Work report'!$A$2:$A$1500,MATCH(ROWS($C$2:C5),'Work report'!$AA$2:$AA$1500,0)),"")) | B5: =IF($C5="","",Setup!$B$4) | C5: =IFERROR(INDEX('Work report'!$R$2:$R$1500,MATCH(ROWS($C$2:C5),'Work report'!$AA$2:$AA$1500,0)),"") | D5: =IFERROR(INDEX('Work report'!$S$2:$S$1500,MATCH(ROWS($D$2:D5),'Work report'!$AA$2:$AA$1500,0)),"") | E5: =IF($C5="","",IFERROR(INDEX('Work report'!$C$2:$C$1500,MATCH(ROWS($C$2:C5),'Work report'!$AA$2:$AA$1500,0)),"")) | F5: =IF($C5="","",IFERROR(INDEX('Work report'!$F$2:$F$1500,MATCH(ROWS($C$2:C5),'Work report'!$AA$2:$AA$1500,0)),"")) | G5: =IF($C5="","",IFERROR(HYPERLINK(INDEX('Work report'!$Q$2:$Q$1500,MATCH(ROWS($C$2:C5),'Work report'!$AA$2:$AA$1500,0)),INDEX('Work report'!$Q$2:$Q$1500,MATCH(ROWS($C$2:C5),'Work report'!$AA$2:$AA$1500,0))),"")) | H5: =IF($C5="","",IFERROR(INDEX('Work report'!$M$2:$M$1500,MATCH(ROWS($C$2:C5),'Work report'!$AA$2:$AA$1500,0)),"")) | I5: =IF($C5="","",IFERROR(INDEX('Work report'!$A$2:$A$1500,MATCH(ROWS($C$2:C5),'Work report'!$AA$2:$AA$1500,0)),"")) | J5: =IF($C5="","",IFERROR(INDEX('Work report'!$I$2:$I$1500,MATCH(ROWS($C$2:C5),'Work report'!$AA$2:$AA$1500,0)),"")) | O5: =IF($C5<>"",$C5,$K5) -> 0 | P5: =IF($D5<>"",$D5,$L5) -> 0 | Q5: =IF($C5<>"","System",IF($K5<>"","Manual",""))
A6: =IF($C6="","",IFERROR(INDEX('Work report'!$A$2:$A$1500,MATCH(ROWS($C$2:C6),'Work report'!$AA$2:$AA$1500,0)),"")) | B6: =IF($C6="","",Setup!$B$4) | C6: =IFERROR(INDEX('Work report'!$R$2:$R$1500,MATCH(ROWS($C$2:C6),'Work report'!$AA$2:$AA$1500,0)),"") | D6: =IFERROR(INDEX('Work report'!$S$2:$S$1500,MATCH(ROWS($D$2:D6),'Work report'!$AA$2:$AA$1500,0)),"") | E6: =IF($C6="","",IFERROR(INDEX('Work report'!$C$2:$C$1500,MATCH(ROWS($C$2:C6),'Work report'!$AA$2:$AA$1500,0)),"")) | F6: =IF($C6="","",IFERROR(INDEX('Work report'!$F$2:$F$1500,MATCH(ROWS($C$2:C6),'Work report'!$AA$2:$AA$1500,0)),"")) | G6: =IF($C6="","",IFERROR(HYPERLINK(INDEX('Work report'!$Q$2:$Q$1500,MATCH(ROWS($C$2:C6),'Work report'!$AA$2:$AA$1500,0)),INDEX('Work report'!$Q$2:$Q$1500,MATCH(ROWS($C$2:C6),'Work report'!$AA$2:$AA$1500,0))),"")) | H6: =IF($C6="","",IFERROR(INDEX('Work report'!$M$2:$M$1500,MATCH(ROWS($C$2:C6),'Work report'!$AA$2:$AA$1500,0)),"")) | I6: =IF($C6="","",IFERROR(INDEX('Work report'!$A$2:$A$1500,MATCH(ROWS($C$2:C6),'Work report'!$AA$2:$AA$1500,0)),"")) | J6: =IF($C6="","",IFERROR(INDEX('Work report'!$I$2:$I$1500,MATCH(ROWS($C$2:C6),'Work report'!$AA$2:$AA$1500,0)),"")) | O6: =IF($C6<>"",$C6,$K6) -> 0 | P6: =IF($D6<>"",$D6,$L6) -> 0 | Q6: =IF($C6<>"","System",IF($K6<>"","Manual",""))
A7: =IF($C7="","",IFERROR(INDEX('Work report'!$A$2:$A$1500,MATCH(ROWS($C$2:C7),'Work report'!$AA$2:$AA$1500,0)),"")) | B7: =IF($C7="","",Setup!$B$4) | C7: =IFERROR(INDEX('Work report'!$R$2:$R$1500,MATCH(ROWS($C$2:C7),'Work report'!$AA$2:$AA$1500,0)),"") | D7: =IFERROR(INDEX('Work report'!$S$2:$S$1500,MATCH(ROWS($D$2:D7),'Work report'!$AA$2:$AA$1500,0)),"") | E7: =IF($C7="","",IFERROR(INDEX('Work report'!$C$2:$C$1500,MATCH(ROWS($C$2:C7),'Work report'!$AA$2:$AA$1500,0)),"")) | F7: =IF($C7="","",IFERROR(INDEX('Work report'!$F$2:$F$1500,MATCH(ROWS($C$2:C7),'Work report'!$AA$2:$AA$1500,0)),"")) | G7: =IF($C7="","",IFERROR(HYPERLINK(INDEX('Work report'!$Q$2:$Q$1500,MATCH(ROWS($C$2:C7),'Work report'!$AA$2:$AA$1500,0)),INDEX('Work report'!$Q$2:$Q$1500,MATCH(ROWS($C$2:C7),'Work report'!$AA$2:$AA$1500,0))),"")) | H7: =IF($C7="","",IFERROR(INDEX('Work report'!$M$2:$M$1500,MATCH(ROWS($C$2:C7),'Work report'!$AA$2:$AA$1500,0)),"")) | I7: =IF($C7="","",IFERROR(INDEX('Work report'!$A$2:$A$1500,MATCH(ROWS($C$2:C7),'Work report'!$AA$2:$AA$1500,0)),"")) | J7: =IF($C7="","",IFERROR(INDEX('Work report'!$I$2:$I$1500,MATCH(ROWS($C$2:C7),'Work report'!$AA$2:$AA$1500,0)),"")) | O7: =IF($C7<>"",$C7,$K7) -> 0 | P7: =IF($D7<>"",$D7,$L7) -> 0 | Q7: =IF($C7<>"","System",IF($K7<>"","Manual",""))
A8: =IF($C8="","",IFERROR(INDEX('Work report'!$A$2:$A$1500,MATCH(ROWS($C$2:C8),'Work report'!$AA$2:$AA$1500,0)),"")) | B8: =IF($C8="","",Setup!$B$4) | C8: =IFERROR(INDEX('Work report'!$R$2:$R$1500,MATCH(ROWS($C$2:C8),'Work report'!$AA$2:$AA$1500,0)),"") | D8: =IFERROR(INDEX('Work report'!$S$2:$S$1500,MATCH(ROWS($D$2:D8),'Work report'!$AA$2:$AA$1500,0)),"") | E8: =IF($C8="","",IFERROR(INDEX('Work report'!$C$2:$C$1500,MATCH(ROWS($C$2:C8),'Work report'!$AA$2:$AA$1500,0)),"")) | F8: =IF($C8="","",IFERROR(INDEX('Work report'!$F$2:$F$1500,MATCH(ROWS($C$2:C8),'Work report'!$AA$2:$AA$1500,0)),"")) | G8: =IF($C8="","",IFERROR(HYPERLINK(INDEX('Work report'!$Q$2:$Q$1500,MATCH(ROWS($C$2:C8),'Work report'!$AA$2:$AA$1500,0)),INDEX('Work report'!$Q$2:$Q$1500,MATCH(ROWS($C$2:C8),'Work report'!$AA$2:$AA$1500,0))),"")) | H8: =IF($C8="","",IFERROR(INDEX('Work report'!$M$2:$M$1500,MATCH(ROWS($C$2:C8),'Work report'!$AA$2:$AA$1500,0)),"")) | I8: =IF($C8="","",IFERROR(INDEX('Work report'!$A$2:$A$1500,MATCH(ROWS($C$2:C8),'Work report'!$AA$2:$AA$1500,0)),"")) | J8: =IF($C8="","",IFERROR(INDEX('Work report'!$I$2:$I$1500,MATCH(ROWS($C$2:C8),'Work report'!$AA$2:$AA$1500,0)),"")) | O8: =IF($C8<>"",$C8,$K8) -> 0 | P8: =IF($D8<>"",$D8,$L8) -> 0 | Q8: =IF($C8<>"","System",IF($K8<>"","Manual",""))
A9: =IF($C9="","",IFERROR(INDEX('Work report'!$A$2:$A$1500,MATCH(ROWS($C$2:C9),'Work report'!$AA$2:$AA$1500,0)),"")) | B9: =IF($C9="","",Setup!$B$4) | C9: =IFERROR(INDEX('Work report'!$R$2:$R$1500,MATCH(ROWS($C$2:C9),'Work report'!$AA$2:$AA$1500,0)),"") | D9: =IFERROR(INDEX('Work report'!$S$2:$S$1500,MATCH(ROWS($D$2:D9),'Work report'!$AA$2:$AA$1500,0)),"") | E9: =IF($C9="","",IFERROR(INDEX('Work report'!$C$2:$C$1500,MATCH(ROWS($C$2:C9),'Work report'!$AA$2:$AA$1500,0)),"")) | F9: =IF($C9="","",IFERROR(INDEX('Work report'!$F$2:$F$1500,MATCH(ROWS($C$2:C9),'Work report'!$AA$2:$AA$1500,0)),"")) | G9: =IF($C9="","",IFERROR(HYPERLINK(INDEX('Work report'!$Q$2:$Q$1500,MATCH(ROWS($C$2:C9),'Work report'!$AA$2:$AA$1500,0)),INDEX('Work report'!$Q$2:$Q$1500,MATCH(ROWS($C$2:C9),'Work report'!$AA$2:$AA$1500,0))),"")) | H9: =IF($C9="","",IFERROR(INDEX('Work report'!$M$2:$M$1500,MATCH(ROWS($C$2:C9),'Work report'!$AA$2:$AA$1500,0)),"")) | I9: =IF($C9="","",IFERROR(INDEX('Work report'!$A$2:$A$1500,MATCH(ROWS($C$2:C9),'Work report'!$AA$2:$AA$1500,0)),"")) | J9: =IF($C9="","",IFERROR(INDEX('Work report'!$I$2:$I$1500,MATCH(ROWS($C$2:C9),'Work report'!$AA$2:$AA$1500,0)),"")) | O9: =IF($C9<>"",$C9,$K9) -> 0 | P9: =IF($D9<>"",$D9,$L9) -> 0 | Q9: =IF($C9<>"","System",IF($K9<>"","Manual",""))
A10: =IF($C10="","",IFERROR(INDEX('Work report'!$A$2:$A$1500,MATCH(ROWS($C$2:C10),'Work report'!$AA$2:$AA$1500,0)),"")) | B10: =IF($C10="","",Setup!$B$4) | C10: =IFERROR(INDEX('Work report'!$R$2:$R$1500,MATCH(ROWS($C$2:C10),'Work report'!$AA$2:$AA$1500,0)),"") | D10: =IFERROR(INDEX('Work report'!$S$2:$S$1500,MATCH(ROWS($D$2:D10),'Work report'!$AA$2:$AA$1500,0)),"") | E10: =IF($C10="","",IFERROR(INDEX('Work report'!$C$2:$C$1500,MATCH(ROWS($C$2:C10),'Work report'!$AA$2:$AA$1500,0)),"")) | F10: =IF($C10="","",IFERROR(INDEX('Work report'!$F$2:$F$1500,MATCH(ROWS($C$2:C10),'Work report'!$AA$2:$AA$1500,0)),"")) | G10: =IF($C10="","",IFERROR(HYPERLINK(INDEX('Work report'!$Q$2:$Q$1500,MATCH(ROWS($C$2:C10),'Work report'!$AA$2:$AA$1500,0)),INDEX('Work report'!$Q$2:$Q$1500,MATCH(ROWS($C$2:C10),'Work report'!$AA$2:$AA$1500,0))),"")) | H10: =IF($C10="","",IFERROR(INDEX('Work report'!$M$2:$M$1500,MATCH(ROWS($C$2:C10),'Work report'!$AA$2:$AA$1500,0)),"")) | I10: =IF($C10="","",IFERROR(INDEX('Work report'!$A$2:$A$1500,MATCH(ROWS($C$2:C10),'Work report'!$AA$2:$AA$1500,0)),"")) | J10: =IF($C10="","",IFERROR(INDEX('Work report'!$I$2:$I$1500,MATCH(ROWS($C$2:C10),'Work report'!$AA$2:$AA$1500,0)),"")) | O10: =IF($C10<>"",$C10,$K10) -> 0 | P10: =IF($D10<>"",$D10,$L10) -> 0 | Q10: =IF($C10<>"","System",IF($K10<>"","Manual",""))
